Workbook

Sheet Screening
A1: Title | B1: Link | C1: Source | D1: Abstract | E1: Irrelevant title/abstract | F1: Dataset (if not DAIC-WOZ) | G1: Does not regard DAIC-WOZ | H1: Does not use MAE | I1: Does not introduce new model | J1: Not in English | K1: Not retrieved | L1: Discarded after full-text review | M1: Data preprocessing | N1: Data partitioning | O1: Partitions disjoint level | P1: Model description | Q1: Training details | R1: Final model selection | S1: - | T1: Data modality | U1: Dev. MAE | V1: Dev. RMSE | W1: Dev. R2 | X1: Test. MAE | Y1: Test. RMSE | Z1: Test. R2 | AA1: Code available | AB1: Repeated experiments | AC1: Uses interviewer's prompts | AD1: Participant inter-partition leakage | AE1: -- | AF1: Included | AG1: Comment
A2: Hierarchical Attention Transfer Networks for Depression Assessment from Speech | B2: https://doi.org/10.1109/ICASSP40776.2020.9053207 | C2: Scopus | D2: A growing area of mental health research is the search for speech-based objective markers for conditions such as depression. However, when combined with machine learning, this search can be challenging due to a limited amount of annotated training data. In this paper, we propose a novel crosstask approach which transfers attention mechanisms from speech recognition to aid depression severity measurement. This transfer is applied in a two-level hierarchical network which mirrors the natural hierarchical structure of speech. Experiments based on the Distress Analysis Interview Corpus-Wizard of Oz (DAIC-WOZ) dataset, as used in the 2017 Audio/Visual Emotion Challenge, demonstrate the effectiveness of our Hierarchical Attention Transfer Network. On the development set, the proposed approach achieves a root mean square error (RMSE) of 3.85, and a mean absolute error (MAE) of 2.99, on a Patient Health Questionnaire (PHQ)-8 scale [0], [24], while on the test set, it achieves an RMSE of 5.66 and an MAE of 4.28. To the best of our knowledge, these scores represent the best-known speech-only results to date on this corpus. © 2020 IEEE. | E2: FALSE | L2: =IF(OR(Table1[[#This Row],[Does not regard DAIC-WOZ]]=TRUE,Table1[[#This Row],[Does not use MAE]]=TRUE,Table1[[#This Row],[Does not introduce new model]]=TRUE,Table1[[#This Row],[Not in English]]=TRUE,Table1[[#This Row],[Not retrieved]]=TRUE),TRUE,FALSE) -> FALSE | M2: MEL Spectrogram | N2: - | O2: Participant turn | P2: Attention transfer BLSTM | Q2: - | R2: - | T2: A | U2: 2.99 | V2: 3.85 | W2: - | X2: 4.28 | Y2: 5.66 | Z2: - | AA2: No | AB2: No | AC2: Yes | AD2: - | AF2: =IF(NOT(Table1[[#This Row],[Data modality]] = ""), NOT(OR(Table1[[#This Row],[Data preprocessing]] = "-", Table1[[#This Row],[Data partitioning]] = "-", Table1[[#This Row],[Partitions disjoint level]] = "-", Table1[[#This Row],[Model description]] ="-", Table1[[#This Row],[Training details]] = "-", Table1[[#This Row],[Final model selection]] = "-", Table1[[#This Row],[Discarded after full-text review]])),"") -> FALSE | AG2: No information about ASR system training. Neither dataset partition utilized nor description of convergence criteria
A3: PointTransform Networks for automatic depression level prediction via facial keypoints | B3: https://doi.org/10.1016/j.knosys.2024.111951 | C3: ScienceDirect | D3: According to physiological reports, individuals with different levels of depression present various facial dynamic patterns. Thus, researchers have examined facial changes to predict depression severity. However, they often use facial images or videos of the subjects, which increases the risk of privacy leakage. Therefore, we intend to use the mixer layer to process facial keypoint sequences to predict the depression levels. However, the mixer layer cannot guarantee that the output and input sequences have the same temporal properties, which prevents the residual connection from being additive in a physical sense. To this end, we construct a PointTransform Network (PTN). In the constructed model, a Mixer Attention Layer (MAL) and a Token Sequence Aggregation (TSA) module are proposed. The proposed MAL embeds the results of channel-communication and token-communication into the sequence in the form of weights through the attention mechanism, which maintains the temporal order among tokens in the sequence during the calculation process and compensates for the limitations of the mixer layer. The proposed TSA module can integrate the depression level prediction results of all facial keypoints through the attention mechanism. Therefore, the TSA module achieves the unity of decision-level fusion and tensor vectorization. Experiments are conducted on several benchmark databases and the results demonstrate the effectiveness of our method. | E3: FALSE | L3: =IF(OR(Table1[[#This Row],[Does not regard DAIC-WOZ]]=TRUE,Table1[[#This Row],[Does not use MAE]]=TRUE,Table1[[#This Row],[Does not introduce new model]]=TRUE,Table1[[#This Row],[Not in English]]=TRUE,Table1[[#This Row],[Not retrieved]]=TRUE),TRUE,FALSE) -> FALSE | M3: - | N3: - | O3: - | P3: Point Transform Network | Q3: + | R3: - | T3: V | U3: - | V3: - | W3: - | X3: 3.84 | Y3: 5.08 | Z3: - | AA3: No | AB3: No | AC3: - | AD3: - | AF3: =IF(NOT(Table1[[#This Row],[Data modality]] = ""), NOT(OR(Table1[[#This Row],[Data preprocessing]] = "-", Table1[[#This Row],[Data partitioning]] = "-", Table1[[#This Row],[Partitions disjoint level]] = "-", Table1[[#This Row],[Model description]] ="-", Table1[[#This Row],[Training details]] = "-", Table1[[#This Row],[Final model selection]] = "-", Table1[[#This Row],[Discarded after full-text review]])),"") -> FALSE | AG3: DAIC-WOZ is used only as an example and no information regarding training on this dataset is provided
A4: Image processing system for velocity measurements in natural convection flows | B4: https://doi.org/10.1016/0029-5493(91)90270-R | C4: ScienceDirect | D4: An image processing system based on a particle-tracking method has been developed to measure quantitatively at one time the two-dimensional velocity components arising in natural convection flows. The analysis of the image data proceeds automatically, due in part to the video recording system utilized in our method. The image processing system was applied to the natural convection flows in a 1/10 scale basic reactor model. The velocity vectors and the vorticities were obtained under transient and steady states in different experimental cases, enabling us to examine in detail the transition of the flow patterns and other aspects under different experimental conditions. The uncertainty of this system was evaluated for use in our experiments and it was confirmed that the margin of error is acceptable. | E4: TRUE | L4: =IF(OR(Table1[[#This Row],[Does not regard DAIC-WOZ]]=TRUE,Table1[[#This Row],[Does not use MAE]]=TRUE,Table1[[#This Row],[Does not introduce new model]]=TRUE,Table1[[#This Row],[Not in English]]=TRUE,Table1[[#This Row],[Not retrieved]]=TRUE),TRUE,FALSE) -> FALSE | AF4: =IF(NOT(Table1[[#This Row],[Data modality]] = ""), NOT(OR(Table1[[#This Row],[Data preprocessing]] = "-", Table1[[#This Row],[Data partitioning]] = "-", Table1[[#This Row],[Partitions disjoint level]] = "-", Table1[[#This Row],[Model description]] ="-", Table1[[#This Row],[Training details]] = "-", Table1[[#This Row],[Final model selection]] = "-", Table1[[#This Row],[Discarded after full-text review]])),"")
A5: Multilevel depression status detection based on fine-grained prompt learning | B5: https://doi.org/10.1016/j.patrec.2024.01.005 | C5: ScienceDirect | D5: As a common psychological disorder, depression is generally detected based on scales and interviews, which are often affected by subjective or environmental factors. In order to assist in the diagnosis, automatic depression detection (ADD) is developed to provide an objective, efficient, and convenient technique based on the analysis of different psychophysiological data. Among them, text is one of the most frequently used modalities in the research field of ADD. Despite its success, several key issues still need to be addressed. Specifically, binary detection performed in the classical ADD methods cannot satisfy the demand for early detection tasks. Therefore, a more fine-grained analysis of depression status is highly needed. Moreover, due to factors such as small dataset size and improper organization of interview texts by selecting response texts only or choosing topics subjectively, insufficient learnable representations for depression detection are inevitable. To tackle these issues, we propose a multilevel depression status detection approach based on fine-grained prompt learning, called MDSD-FGPL. In our method, we design multiple sets of prompts from coarse-grained to fine-grained and therefore train the language model with features extracted from different depressive levels. We also reorganize the interview text at the question-response level and utilize the attention mechanism to capture and fuse the key features. Specifically, two model branches are constructed based on pre-trained language models for extracting comprehensive semantic features and depression-specific semantic tendencies, respectively. Our method was evaluated on the DAIC-WOZ dataset, showing satisfying performance in fine-grained depression detection. Additionally, our method achieves a state-of-the-art F1-score of 0.8276 in the coarse-grained binary classification. | E5: FALSE | L5: =IF(OR(Table1[[#This Row],[Does not regard DAIC-WOZ]]=TRUE,Table1[[#This Row],[Does not use MAE]]=TRUE,Table1[[#This Row],[Does not introduce new model]]=TRUE,Table1[[#This Row],[Not in English]]=TRUE,Table1[[#This Row],[Not retrieved]]=TRUE),TRUE,FALSE) -> FALSE | M5: Default transcriptions | N5: Default | O5: Participant turn | P5: T5 and BERT embeddings fusion | Q5: - | R5: - | T5: T | U5: - | V5: - | W5: - | X5: 5.28 | Y5: - | Z5: - | AA5: No | AB5: No | AC5: Yes | AD5: No | AF5: =IF(NOT(Table1[[#This Row],[Data modality]] = ""), NOT(OR(Table1[[#This Row],[Data preprocessing]] = "-", Table1[[#This Row],[Data partitioning]] = "-", Table1[[#This Row],[Partitions disjoint level]] = "-", Table1[[#This Row],[Model description]] ="-", Table1[[#This Row],[Training details]] = "-", Table1[[#This Row],[Final model selection]] = "-", Table1[[#This Row],[Discarded after full-text review]])),"") -> FALSE | AG5: No information on model training and selection (hparams, convergence criteria) is provided
A6: A random forest regression method with selected-text feature for depression assessment | B6: https://doi.org/10.1145/3133944.3133951 | C6: Scopus | D6: Audio/visual and mood disorder cues have been recently explored to assist psychologists and psychiatrists in Depression Diagnosis. in this paper, we propose a random forest method with a Selected-Text feature which is according to the analysis on the transcript in different depressive levels. The files are consisted of sleep quality, PTSD/Depression Diagnostic, successive treatment, personal preference and feeling. Experiments are carried out on the Distress Analysis Interview Corpus-Wizard of Oz (DAIC-WOZ) database[6]. Comparing with results obtained with audio based, video based or multi-feature based cascade decision-level fusion features, Selected-Text feature based method has obtained very promising results on the development and test sets. The root mean square error(RMSE) reaches 4.7, and mean absolute error(MAE) reaches 3.9, which are better than the baseline result, i.e. 7.05/5.66. © 2017 Copyright held by the owner/author(s). | E6: FALSE | L6: =IF(OR(Table1[[#This Row],[Does not regard DAIC-WOZ]]=TRUE,Table1[[#This Row],[Does not use MAE]]=TRUE,Table1[[#This Row],[Does not introduce new model]]=TRUE,Table1[[#This Row],[Not in English]]=TRUE,Table1[[#This Row],[Not retrieved]]=TRUE),TRUE,FALSE) -> FALSE | M6: Manual feature assignment | N6: Default | O6: Interview | P6: Cascade Random Forest Regression | Q6: - | R6: N/A | T6: V-A-T | U6: - | V6: - | W6: - | X6: 3.87 | Y6: 4.98 | Z6: - | AA6: No | AB6: No | AC6: Yes | AD6: No | AF6: =IF(NOT(Table1[[#This Row],[Data modality]] = ""), NOT(OR(Table1[[#This Row],[Data preprocessing]] = "-", Table1[[#This Row],[Data partitioning]] = "-", Table1[[#This Row],[Partitions disjoint level]] = "-", Table1[[#This Row],[Model description]] ="-", Table1[[#This Row],[Training details]] = "-", Table1[[#This Row],[Final model selection]] = "-", Table1[[#This Row],[Discarded after full-text review]])),"") -> FALSE | AG6: Detailed model specifications (e.g. number of trees in random forest) are not disclosed. Manually prepared features from text per interview may imply bias. Looks a bit similar to https://doi.org/10.1145/3133944.3133951 which was published year before.
A7: MPDRM: A Multi-Scale Personalized Depression Recognition Model via facial movements | B7: https://doi.org/10.1016/j.neucom.2025.129669 | C7: ScienceDirect | D7: Automatic depression recognition based on facial movements in videos has become a research hotspot. However, existing methods tend to confuse individual inherent facial behavioral habits with characteristics specific to depression, which leads to misjudgments. To address this, we propose a Multi-scale Personalized Depression Recognition Model (MPDRM) that mitigates the negative impact of individual differences, enabling the model to focus on general and robust facial depression cues. The proposed model consists of three main components: the Multi-scale Depression Feature Network (MDFN), the Multi-scale Personality Feature Network (MPFN), and the Relational Attention Recognition Module (RARM). The MDFN extracts depression-related information, while the contrastive learning-based MPFN extracts stable personalized information. In both MDFN and MPFN, we insert the Multi-scale Motion Pattern Extraction Module (MMP) to capture rich multi-scale spatiotemporal facial features. Finally, the RARM is designed to enhance the representation of depression and output the results. Cross-validation on a specifically constructed longitudinal dataset demonstrates that our model outperforms other models. Experimental results indicate that suppressing personalized information of facial movements can effectively improve the accuracy of depression recognition. | E7: FALSE | F7: custom | G7: TRUE | L7: =IF(OR(Table1[[#This Row],[Does not regard DAIC-WOZ]]=TRUE,Table1[[#This Row],[Does not use MAE]]=TRUE,Table1[[#This Row],[Does not introduce new model]]=TRUE,Table1[[#This Row],[Not in English]]=TRUE,Table1[[#This Row],[Not retrieved]]=TRUE),TRUE,FALSE) -> TRUE | AF7: =IF(NOT(Table1[[#This Row],[Data modality]] = ""), NOT(OR(Table1[[#This Row],[Data preprocessing]] = "-", Table1[[#This Row],[Data partitioning]] = "-", Table1[[#This Row],[Partitions disjoint level]] = "-", Table1[[#This Row],[Model description]] ="-", Table1[[#This Row],[Training details]] = "-", Table1[[#This Row],[Final model selection]] = "-", Table1[[#This Row],[Discarded after full-text review]])),"")
A8: Conversational assessment using artificial intelligence is as clinically useful as depression scales and preferred by users | B8: https://doi.org/10.1016/j.jad.2024.01.212 | C8: ScienceDirect | D8: Background | E8: TRUE | L8: =IF(OR(Table1[[#This Row],[Does not regard DAIC-WOZ]]=TRUE,Table1[[#This Row],[Does not use MAE]]=TRUE,Table1[[#This Row],[Does not introduce new model]]=TRUE,Table1[[#This Row],[Not in English]]=TRUE,Table1[[#This Row],[Not retrieved]]=TRUE),TRUE,FALSE) -> FALSE | AF8: =IF(NOT(Table1[[#This Row],[Data modality]] = ""), NOT(OR(Table1[[#This Row],[Data preprocessing]] = "-", Table1[[#This Row],[Data partitioning]] = "-", Table1[[#This Row],[Partitions disjoint level]] = "-", Table1[[#This Row],[Model description]] ="-", Table1[[#This Row],[Training details]] = "-", Table1[[#This Row],[Final model selection]] = "-", Table1[[#This Row],[Discarded after full-text review]])),"")
A9: An automatic diagnostic network using skew-robust adversarial discriminative domain adaptation to evaluate the severity of depression | B9: https://doi.org/10.1016/j.cmpb.2019.01.006 | C9: ScienceDirect | D9: Background and Objective | E9: FALSE | L9: =IF(OR(Table1[[#This Row],[Does not regard DAIC-WOZ]]=TRUE,Table1[[#This Row],[Does not use MAE]]=TRUE,Table1[[#This Row],[Does not introduce new model]]=TRUE,Table1[[#This Row],[Not in English]]=TRUE,Table1[[#This Row],[Not retrieved]]=TRUE),TRUE,FALSE) -> FALSE | M9: Uses pretraining on TSATC. Extracts features from auto-selected text fragments | N9: 107 interviews for training, 35 for testing | O9: Interview | P9: Hierarchical Attention Network | Q9: - | R9: - | T9: T | U9: - | V9: - | W9: - | X9: 4.08 | Y9: 5.13 | Z9: - | AA9: No | AB9: No | AC9: Yes | AD9: Yes | AF9: =IF(NOT(Table1[[#This Row],[Data modality]] = ""), NOT(OR(Table1[[#This Row],[Data preprocessing]] = "-", Table1[[#This Row],[Data partitioning]] = "-", Table1[[#This Row],[Partitions disjoint level]] = "-", Table1[[#This Row],[Model description]] ="-", Table1[[#This Row],[Training details]] = "-", Table1[[#This Row],[Final model selection]] = "-", Table1[[#This Row],[Discarded after full-text review]])),"") -> FALSE | AG9: No information on convergence criteria for HAN pretraining. Randomly sampled QA pairs for knowledge transfer, which implies participant inter-partition leakage
A10: FPT-Former: A Flexible Parallel Transformer of Recognizing Depression by Using Audiovisual Expert-Knowledge-Based Multimodal Measures | B10: https://doi.org/10.1155/2024/1564574 | C10: Scopus | D10: Background and Objective. Currently, depression is a widespread global issue that imposes a significant burden and disability on individuals, families, and society. Deep learning (DL) has emerged as a valuable approach for automatically detecting depression by extracting cues from audiovisual data and making a diagnosis. PHQ-8 is considered a validated diagnostic tool for depressive disorders in clinical studies, and the objective of this experiment is to improve the accuracy of PHQ-8 prediction. Furthermore, this paper aims to demonstrate the effectiveness of expert knowledge in depression diagnosis and discuss a novel multimodal network architecture. Methods. This research paper focuses on multimodal depression analysis, proposing a flexible parallel transformer (FPT) model capable of extracting data from three distinct modalities (i.e., one video and two audio descriptors). The FPT-Former model incorporates three paths, each using expert-knowledge-based descriptors from one modality as inputs. These descriptors are represented into 32 features by the encoder part of a transformer module, and these features are fused to realize the final regression of PHQ-8 score. The extended distress analysis interview corpus (E-DAIC) is an expansion of WOZ-DAIC which comprises semiclinical interviews intended to assist in the diagnosis of psychological distress conditions. It encompasses a sample size of 275 participants, and in this study, it was utilized to test the model in a way of 10-fold cross-validation. Results. The FPT presented herein achieved comparable performance to the state-of-the-art works, with a root mean square error (RMSE) of 4.80 and a mean absolute error (MAE) of 4.58. The ablation experiments demonstrate that the three-modality-fused model outperforms other two-modality-fused and single-modality models. While using a PHQ-8 score threshold of 10, the accuracy of the depression classification is 0.79. Conclusions. Leveraging the strength of expert-knowledge-based multimodal measures and parallel transformer structure, the FPT model exhibits promising performance in depression detection. This model improved the accuracy of depression diagnosis through audio and video, and it also proved the effectiveness of using expert-knowledge in the diagnosis of depression. The traits of flexible structure, high predictive efficiency, and secure privacy protection make our model a promotable intelligent system in mental healthcare. © 2024 Yifu Li et al. | E10: FALSE | F10: E-DAIC | G10: TRUE | L10: =IF(OR(Table1[[#This Row],[Does not regard DAIC-WOZ]]=TRUE,Table1[[#This Row],[Does not use MAE]]=TRUE,Table1[[#This Row],[Does not introduce new model]]=TRUE,Table1[[#This Row],[Not in English]]=TRUE,Table1[[#This Row],[Not retrieved]]=TRUE),TRUE,FALSE) -> TRUE | AF10: =IF(NOT(Table1[[#This Row],[Data modality]] = ""), NOT(OR(Table1[[#This Row],[Data preprocessing]] = "-", Table1[[#This Row],[Data partitioning]] = "-", Table1[[#This Row],[Partitions disjoint level]] = "-", Table1[[#This Row],[Model description]] ="-", Table1[[#This Row],[Training details]] = "-", Table1[[#This Row],[Final model selection]] = "-", Table1[[#This Row],[Discarded after full-text review]])),"")
A11: Improving depression prediction using a novel feature selection algorithm coupled with context-aware analysis | B11: https://doi.org/10.1016/j.jad.2021.09.001 | C11: ScienceDirect | D11: Background: Developing machine learning based depression prediction method with information from long-term recordings is important and challenging to clinical diagnosis of depression. Methods: We developed a novel two-stage feature selection algorithm conducted on the high-dimensional (over thirty thousand) features constructed by a context-aware analysis on the data set of DAIC-WOZ, including audio, video, and semantic features. The prediction performance was compared with seven reference models. The preferred topics and feature categories related to the retained features were also analyzed respectively. Results: Parsimonious subsets (tens of features) were selected by the proposed method in each case of prediction. We obtained the best performance in depression classification with F1-score as 0.96 (0.67), Precision as 1.00 (0.63), and Recall as 0.92 (0.71) on the development set (test set). We also achieved promising results in depression severity estimation with RMSE as 4.43 (5.11) and MAE as 3.22 (3.98), having a marginal difference with the best reference model (random forest with ‘Selected-Text’ features). Five most important topics related to depression were revealed. The audio features were predominant to the other feature categories in depression classification while the contributions of the three feature categories to severity estimation were almost equal. Limitations: More depression samples in the database we used should be further included. The second stage of feature selection is relatively time-consuming. Conclusion: This pipeline of depression recognition as well as the preferred topics and feature categories are expected to be useful in supporting the diagnosis of psychological distress conditions. | E11: FALSE | L11: =IF(OR(Table1[[#This Row],[Does not regard DAIC-WOZ]]=TRUE,Table1[[#This Row],[Does not use MAE]]=TRUE,Table1[[#This Row],[Does not introduce new model]]=TRUE,Table1[[#This Row],[Not in English]]=TRUE,Table1[[#This Row],[Not retrieved]]=TRUE),TRUE,FALSE) -> FALSE | M11: Topic-based feature selection | N11: 107 interviews for training, 33 for development, 46 for testing | O11: Interview | P11: SVM | Q11: + | R11: - | T11: V-A-T | U11: 3.22 | V11: 4.43 | W11: - | X11: 3.98 | Y11: 5.11 | Z11: - | AA11: Yes | AB11: Yes | AC11: Yes | AD11: No | AF11: =IF(NOT(Table1[[#This Row],[Data modality]] = ""), NOT(OR(Table1[[#This Row],[Data preprocessing]] = "-", Table1[[#This Row],[Data partitioning]] = "-", Table1[[#This Row],[Partitions disjoint level]] = "-", Table1[[#This Row],[Model description]] ="-", Table1[[#This Row],[Training details]] = "-", Table1[[#This Row],[Final model selection]] = "-", Table1[[#This Row],[Discarded after full-text review]])),"") -> FALSE | AG11: Grid search on train-val split is mentioned, however target metric used for best hyperparameter combination selection is not disclosed. Topics extraction from Interviewer' responses was performed on entire DAIC corpus and not exclusively on training set. Strongly relies on Interviewer's responses
A12: Multi-feature deep supervised voiceprint adversarial network for depression recognition from speech | B12: https://doi.org/10.1016/j.bspc.2023.105704 | C12: ScienceDirect | D12: Depression can induce a range of physiological effects, leading to notable distinctions in the acoustic characteristics exhibited by individuals with depression as opposed to those without. Designing efficient algorithms to accurately identify depression through speech poses a formidable challenge. In this paper, we propose the Multi-Feature Deep Supervised Voiceprint Adversarial Network (MFDS-VAN) for audio-based depression recognition. The MFDS-VAN assimilates extracted acoustic features and the audio waveform, subsequently generating predictions regarding the depression score. In order to attain more robust and discriminative spatial–temporal features associated with depression, the Encoding Network module merges long-term and short-term acoustic features with the unprocessed audio waveform, while the Regression Network module enables the prediction of the depression score. The Deep Supervised Regression algorithm is designed by combining GE2E clustering and Huber regression for better network optimization. Furthermore, to enhance the representation of the MFDS-VAN while diminishing the influence of individual voiceprint information, we propose the Voiceprint Adversarial Network. Experimental results conducted on AVEC 2013, AVEC 2014, and AVEC 2017 datasets demonstrate that the MFDS-VAN significantly enhances robustness and performance in speech-based depression recognition. Our model achieves competitive results when compared to recent audio-based methodologies. | E12: FALSE | F12: AVEC 2013, AVEC 2014, and AVEC 2017 | G12: TRUE | L12: =IF(OR(Table1[[#This Row],[Does not regard DAIC-WOZ]]=TRUE,Table1[[#This Row],[Does not use MAE]]=TRUE,Table1[[#This Row],[Does not introduce new model]]=TRUE,Table1[[#This Row],[Not in English]]=TRUE,Table1[[#This Row],[Not retrieved]]=TRUE),TRUE,FALSE) -> TRUE | AF12: =IF(NOT(Table1[[#This Row],[Data modality]] = ""), NOT(OR(Table1[[#This Row],[Data preprocessing]] = "-", Table1[[#This Row],[Data partitioning]] = "-", Table1[[#This Row],[Partitions disjoint level]] = "-", Table1[[#This Row],[Model description]] ="-", Table1[[#This Row],[Training details]] = "-", Table1[[#This Row],[Final model selection]] = "-", Table1[[#This Row],[Discarded after full-text review]])),"")
A13: PIE: A Personalized Information Embedded model for text-based depression detection | B13: https://doi.org/10.1016/j.ipm.2024.103830 | C13: ScienceDirect | D13: Depression detection based on text analysis has emerged as a research hotspot. Existing research indicates that patients’ personalized characteristics are the primary factor contributing to differences in reported experiences, which poses challenges for automated depression detection methods. To address this, we pioneered defining the fundamental components of personalized information within the text-based depression detection field and proposed the Personalized Information Embedding (PIE) model. The model narrows the gap between generic clinical symptoms and personalized patient experiences in detection, introducing a novel method for computing personalized information representations. Then, we constructed a unique depression intervention dataset containing 108 cases of subjects, the first longitudinally gathering experimental dataset in text-based depression detection. Extensive experimental evidence demonstrates that compared to advanced models, PIE demonstrates statistically significant improvements in performance (with the maximum reductions in RMSE of 0.309 and MAE of 0.232) and generalizability (with standard deviation reductions in RMSE by 75.43% and MAE by 69.77%), and the out-of-domain generalizability of personalized information representations has been validated on two larger external datasets. Additionally, we conducted case studies to analyze how personalized information leads to improved model capabilities. This research serves as a pilot and reference for developing personalized models in text-based depression detection. | E13: FALSE | F13: custom | G13: TRUE | L13: =IF(OR(Table1[[#This Row],[Does not regard DAIC-WOZ]]=TRUE,Table1[[#This Row],[Does not use MAE]]=TRUE,Table1[[#This Row],[Does not introduce new model]]=TRUE,Table1[[#This Row],[Not in English]]=TRUE,Table1[[#This Row],[Not retrieved]]=TRUE),TRUE,FALSE) -> TRUE | AF13: =IF(NOT(Table1[[#This Row],[Data modality]] = ""), NOT(OR(Table1[[#This Row],[Data preprocessing]] = "-", Table1[[#This Row],[Data partitioning]] = "-", Table1[[#This Row],[Partitions disjoint level]] = "-", Table1[[#This Row],[Model description]] ="-", Table1[[#This Row],[Training details]] = "-", Table1[[#This Row],[Final model selection]] = "-", Table1[[#This Row],[Discarded after full-text review]])),"")
A14: Autoencoder based on cepstrum separation to detect depression from speech | B14: https://doi.org/10.1145/3452940.3453038 | C14: Scopus | D14: Depression has become a common mental disorder that plagues more and more people. This paper uses speech signals to study a method for predicting the degree of depression and help clinicians judge the degree of depression in patients. In this paper, a autoencoder model based on Bidirectional Gated Recurrent Unit (BiGRU) is proposed to extract deep speech features, with the original speech as the network input, the signal after the cepstrum separation as the training target. In this model, we take the original speech as the input of the network, and the homomorphic speech as the training target of the model. The long-term deep features extracted by the model and the short-time shallow features extracted by the Opensmile toolkit were sent into Random Forest (RF) respectively, and finally the Support Vector Regression (SVR) was used for decision fusion recognition. In this paper, experiments are conducted on the DAIC-WOZ data set, and the Root Mean Square Error (RMSE) is 5.68 and the Mean Absolute Error (MAE) is 4.64. © 2020 ACM. | E14: FALSE | L14: =IF(OR(Table1[[#This Row],[Does not regard DAIC-WOZ]]=TRUE,Table1[[#This Row],[Does not use MAE]]=TRUE,Table1[[#This Row],[Does not introduce new model]]=TRUE,Table1[[#This Row],[Not in English]]=TRUE,Table1[[#This Row],[Not retrieved]]=TRUE),TRUE,FALSE) -> FALSE | M14: Interviewer utterance removal, participant utterance concatenation and split into 15s fragments | N14: Random 80/20 train/test split | O14: Concatenated participant turns into 15s audio segments | P14: BiGRU | Q14: - | R14: 50-times repeated experiment | T14: A | U14: 4.64 | V14: 5.68 | W14: - | X14: - | Y14: - | Z14: - | AA14: No | AB14: Yes | AC14: No | AD14: Yes | AF14: =IF(NOT(Table1[[#This Row],[Data modality]] = ""), NOT(OR(Table1[[#This Row],[Data preprocessing]] = "-", Table1[[#This Row],[Data partitioning]] = "-", Table1[[#This Row],[Partitions disjoint level]] = "-", Table1[[#This Row],[Model description]] ="-", Table1[[#This Row],[Training details]] = "-", Table1[[#This Row],[Final model selection]] = "-", Table1[[#This Row],[Discarded after full-text review]])),"") -> FALSE | AG14: No information for convergence criteria, no information on handcrafted features preparation, ambiguous description of train-val-test split
A15: Facial action units guided graph representation learning for multimodal depression detection | B15: https://doi.org/10.1016/j.neucom.2024.129106 | C15: ScienceDirect | D15: Depression has become highly prevalent worldwide. Applying technological solutions to compensate for limited resources is crucial for enabling improved early detection and intervention of depressive emotions. Facial expressions and speech are often utilized to assess depression levels since they contain rich emotional cues. However, the inherent inter-individual variability presented in facial expressions and speech introduces noise and redundancy into these cues. Since Facial Action Units (FAUs) represent identity-free facial muscle movements, we proposed a novel FAU-Guided Fusion (FAU-GF) strategy that extracts less noisy and redundant emotional features from human facial and speech behaviors. Moreover, depressive symptoms manifest in a recurrent, episodic, and intermittent fashion, with disjointed temporal connections. To enhance temporal dependency extraction, we innovatively represent temporal events as a graph structure and designed a Feature-Aware Edge Updater (FAEU) to better model contextual dependencies by learning the edges. Subsequently, we adopted Graph Attention Networks (GAT) to update the nodes and edges. After that, a Temporal Attention (TA) module is constructed to selectively focus on informative affect dynamics for each node. Finally, a Depression Predictor is used to assess the depression severity level. The proposed model was evaluated on the AVEC 2014 and AVEC 2019 datasets. Experimental results demonstrate that our model outperforms existing methods. | E15: FALSE | F15: AVEC2014 AVEC2019 | G15: TRUE | L15: =IF(OR(Table1[[#This Row],[Does not regard DAIC-WOZ]]=TRUE,Table1[[#This Row],[Does not use MAE]]=TRUE,Table1[[#This Row],[Does not introduce new model]]=TRUE,Table1[[#This Row],[Not in English]]=TRUE,Table1[[#This Row],[Not retrieved]]=TRUE),TRUE,FALSE) -> TRUE | AF15: =IF(NOT(Table1[[#This Row],[Data modality]] = ""), NOT(OR(Table1[[#This Row],[Data preprocessing]] = "-", Table1[[#This Row],[Data partitioning]] = "-", Table1[[#This Row],[Partitions disjoint level]] = "-", Table1[[#This Row],[Model description]] ="-", Table1[[#This Row],[Training details]] = "-", Table1[[#This Row],[Final model selection]] = "-", Table1[[#This Row],[Discarded after full-text review]])),"")
A16: RADIANCE: Reliable and interpretable depression detection from speech using transformer | B16: https://doi.org/10.1016/j.compbiomed.2024.109325 | C16: ScienceDirect | D16: Depression is a common but severe mental disorder that adversely impacts the ability of an individual to function normally in their day-to-day life. A majority of depressed individuals remain undiagnosed due to factors such as social stigma and a shortage of healthcare professionals. Consequently, several Machine Learning and Deep Learning (DL) models based on speech have been proposed for automatic depression detection, with the latter generally outperforming the former. However, DL models are blackbox and offer no transparency. In contrast, healthcare professionals prefer models that provide interpretability besides being accurate. In this direction, we propose a method RADIANCE (Reliable AnD InterpretAble depressioN deteCtion transformErs). RADIANCE incorporates a novel FilterBank VIsion Transformer (FBViT) network, which provides the symptoms of depression as interpretable features. Additionally, we employ a novel loss function that handles the class imbalance issue in the datasets. It also incorporates a penalty term that addresses the hierarchy of misclassification errors. We also propose a reliability predictor based on low-level descriptors that provides a reliability score to indicate the trustworthiness of the prediction by FBViT. Furthermore, in contrast to the conventional averaging and majority pooling, RADIANCE consolidates predictions from multiple clips of the input audio by intricately weighing each prediction based on its reliability score, ensuring a more accurate overall prediction. RADIANCE outperforms the state-of-the-art depression detection methods, achieving an accuracy of 89.36%, 80.36%, and 94.44% over the DAIC-WOZ, E-DAIC, and CMDC datasets, respectively. Further, RADIANCE achieves MAE scores of 3.27 and 5.04 on the DAIC-WOZ and E-DAIC datasets, respectively. | E16: FALSE | L16: =IF(OR(Table1[[#This Row],[Does not regard DAIC-WOZ]]=TRUE,Table1[[#This Row],[Does not use MAE]]=TRUE,Table1[[#This Row],[Does not introduce new model]]=TRUE,Table1[[#This Row],[Not in English]]=TRUE,Table1[[#This Row],[Not retrieved]]=TRUE),TRUE,FALSE) -> FALSE | M16: Overlapping sliding window. MEL filterbank | N16: - | O16: Interview | P16: FilterBank VIsion Transformer | Q16: - | R16: Grid search | T16: A | U16: - | V16: - | W16: - | X16: - | Y16: - | Z16: - | AA16: No | AB16: No | AC16: Yes | AD16: - | AF16: =IF(NOT(Table1[[#This Row],[Data modality]] = ""), NOT(OR(Table1[[#This Row],[Data preprocessing]] = "-", Table1[[#This Row],[Data partitioning]] = "-", Table1[[#This Row],[Partitions disjoint level]] = "-", Table1[[#This Row],[Model description]] ="-", Table1[[#This Row],[Training details]] = "-", Table1[[#This Row],[Final model selection]] = "-", Table1[[#This Row],[Discarded after full-text review]])),"") -> FALSE | AG16: No information on dataset partitioning. No details on model training and convergence criteria. Reported results are for unknown partition
A17: A multimodal fusion model with multi-level attention mechanism for depression detection | B17: https://doi.org/10.1016/j.bspc.2022.104561 | C17: ScienceDirect | D17: Depression is a common mental illness that affects the physical and mental health of hundreds of millions of people around the world. Therefore, designing an efficient and robust depression detection model is an urgent research task. In order to fully extract depression features, we systematically analyze audio-visual and text data related to depression, and proposes a multimodal fusion model with multi-level attention mechanism (MFM-Att) for depression detection. The method is mainly divided into two stages: the first stage utilizes two LSTMs and a Bi-LSTM with attention mechanism to learn multi-view audio feature, visual feature and rich text feature, respectively. In the second stage, the output features of the three modalities are sent into the attention fusion network (AttFN) to obtain effective depression information, aiming to make use of the diversity and complementarity between modalities for depression detection. It is worth noting that the multi-level attention mechanism can not only extract valuable depressive features of intra-modality, but also learn the correlations of inter-modality, thereby improving the overall performance of the model by reducing the influence of redundant information. MFM-Att model is evaluated on the DAIC-WOZ dataset, and the result outperforms state-of-the-art models in terms of root mean square error (RMSE). | E17: FALSE | L17: =IF(OR(Table1[[#This Row],[Does not regard DAIC-WOZ]]=TRUE,Table1[[#This Row],[Does not use MAE]]=TRUE,Table1[[#This Row],[Does not introduce new model]]=TRUE,Table1[[#This Row],[Not in English]]=TRUE,Table1[[#This Row],[Not retrieved]]=TRUE),TRUE,FALSE) -> FALSE | M17: - | N17: - | O17: - | P17: Tensor Fusion Network (MLP) | Q17: - | R17: - | T17: V-A-T | U17: - | V17: - | W17: - | X17: - | Y17: - | Z17: - | AA17: No | AB17: No | AC17: - | AD17: - | AF17: =IF(NOT(Table1[[#This Row],[Data modality]] = ""), NOT(OR(Table1[[#This Row],[Data preprocessing]] = "-", Table1[[#This Row],[Data partitioning]] = "-", Table1[[#This Row],[Partitions disjoint level]] = "-", Table1[[#This Row],[Model description]] ="-", Table1[[#This Row],[Training details]] = "-", Table1[[#This Row],[Final model selection]] = "-", Table1[[#This Row],[Discarded after full-text review]])),"") -> FALSE | AG17: Missing information regarding training details (e.g. dropout). Paper describes several hyperparameters combinations but does not disclose final model selection criteria. Vague data preprocessing description. No information on data partitioning and disjoint level
A18: Exploring the Capabilities of a Language Model-Only Approach for Depression Detection in Text Data | B18: https://doi.org/10.1109/BHI58575.2023.10313367 | C18: Scopus | D18: Depression is a prevalent and debilitating mental health condition that requires accurate and efficient detection for timely and effective treatment. In this study, we utilized the E-DAIC (Extended Distress Analysis Interview Corpus-Wizard-of-Oz) dataset, an extended version of the DAIC-WOZ dataset, which consists of semi-clinical interviews conducted by an animated virtual interviewer called Ellie, controlled by a human interviewer in another room. With 275 participants, the E-DAIC dataset represents a valuable resource for investigating depression detection methods. Our aim is to predict PHQ-8 scores through text analysis. Leveraging state-of-the-art speech processing, LLM-based text summarization, and a specialized depression detection module, we demonstrate the transformative potential of language data analysis in enhancing depression screening. By overcoming the limitations of manual feature extraction methods, our automated techniques provide a more efficient and effective means of evaluating depression. In our evaluation, we achieve robust accuracy on the development set of the E-DAIC dataset, with a Mean Absolute Error (MAE) of 3.65 in estimating PHQ-8 scores from recorded interviews. This remarkable performance highlights the efficacy of our approach in automatically predicting depression severity. Our research contributes to the growing evidence supporting the use of LLMs in mental health assessment, showcasing the role of innovative technologies in advancing patient care for depression. © 2023 IEEE. | E18: FALSE | F18: E-DAIC | G18: TRUE | L18: =IF(OR(Table1[[#This Row],[Does not regard DAIC-WOZ]]=TRUE,Table1[[#This Row],[Does not use MAE]]=TRUE,Table1[[#This Row],[Does not introduce new model]]=TRUE,Table1[[#This Row],[Not in English]]=TRUE,Table1[[#This Row],[Not retrieved]]=TRUE),TRUE,FALSE) -> TRUE | AF18: =IF(NOT(Table1[[#This Row],[Data modality]] = ""), NOT(OR(Table1[[#This Row],[Data preprocessing]] = "-", Table1[[#This Row],[Data partitioning]] = "-", Table1[[#This Row],[Partitions disjoint level]] = "-", Table1[[#This Row],[Model description]] ="-", Table1[[#This Row],[Training details]] = "-", Table1[[#This Row],[Final model selection]] = "-", Table1[[#This Row],[Discarded after full-text review]])),"")
A19: Speech-Based Depression Detection System Optimized Using Particle Swarm Optimization | B19: https://doi.org/10.1109/NILES63360.2024.10753199 | C19: Scopus | D19: Depression is a prevalent mental disorder, and accurate diagnosis is essential for effective intervention. Traditional diagnostic methods rely on subjective professional judgment, which can introduce bias. To address this challenge, we propose an optimized model that hybridizes Particle Swarm Optimization (PSO), and deep-learning for depression detection and assessment. Our approach leverages Mel-frequency cepstral coefficients (MFCC), Bidirectional Long Short-Term Memory (BiLSTM), and PSO on the audio data. Experiments on the Distress Analysis Interview Corpus Wizard-of-Oz (DAIC-WOZ) dataset demonstrate significant performance improvements. Our model achieves a Root Mean Square Error (RMSE) of 3.82 and a Mean Absolute Error (MAE) of 3.24, outperforming existing state-of-the-art depression detection methods. © 2024 IEEE. | E19: FALSE | L19: =IF(OR(Table1[[#This Row],[Does not regard DAIC-WOZ]]=TRUE,Table1[[#This Row],[Does not use MAE]]=TRUE,Table1[[#This Row],[Does not introduce new model]]=TRUE,Table1[[#This Row],[Not in English]]=TRUE,Table1[[#This Row],[Not retrieved]]=TRUE),TRUE,FALSE) -> FALSE | M19: - | N19: Default | O19: - | P19: PSO, BiLSTM | Q19: - | R19: - | T19: A | U19: 3.24 | V19: 3.82 | W19: - | X19: - | Y19: - | Z19: - | AA19: No | AB19: No | AC19: - | AD19: No | AF19: =IF(NOT(Table1[[#This Row],[Data modality]] = ""), NOT(OR(Table1[[#This Row],[Data preprocessing]] = "-", Table1[[#This Row],[Data partitioning]] = "-", Table1[[#This Row],[Partitions disjoint level]] = "-", Table1[[#This Row],[Model description]] ="-", Table1[[#This Row],[Training details]] = "-", Table1[[#This Row],[Final model selection]] = "-", Table1[[#This Row],[Discarded after full-text review]])),"") -> FALSE | AG19: MFCC features extraction is weakly described (no information regarding audio preprocessing, lack of windowing description). From data preprocessing it’s unclear whether interviewer’s turns are used for the model training. Partitions disjoint level is not disclosed. Training details are not disclosed (optimizer, learning rate, number of epochs). Convergence criteria are not disclosed.
A20: Enhanced Machine Learning Framework for Autonomous Depression Detection Using Modwave Cepstral Fusion and Stochastic Embedding; [УСОВЕРШЕНСТВОВАННАЯ СИСТЕМА МАШИННОГО ОБУЧЕНИЯ ДЛЯ АВТОНОМНОГО ОБНАРУЖЕНИЯ ДЕПРЕССИИ С ИСПОЛЬЗОВАНИЕМ МОДУЛИРОВАННОГО ВЕЙВЛЕТ-КЕПСТРАЛЬНОГО СЛИЯНИЯ И СТОХАСТИЧЕСКОГО ВСТРАИВАНИЯ] | B20: https://doi.org/10.15622/ia.23.6.7 | C20: Scopus | D20: Depression is a prevalent mental illness that requires autonomous detection systems due to its complexity. Existing machine learning techniques face challenges such as background noise sensitivity, slow adaptation speed, and imbalanced data. To address these limitations, this study proposes a novel ModWave Cepstral Fusion and Stochastic Embedding Framework for depression prediction. Then, the Gain Modulated Wavelet Technique removes background noise and normalises audio signals. Difficulties with generalisation, which results in a lack of interpretability, hinder extracting relevant characteristics from speech. To address these issues, an Auto Cepstral Fusion extracts relevant features from speech, capturing temporal and spectral characteristics caused by background voice. Feature selection becomes imperative when choosing relevant features for classification. Selecting irrelevant features can result in overfitting, the curse of dimensionality, and less robustness to noise. Hence, the Principal Stochastic Embedding technique handles high-dimensional data, minimising noise influence and dimensionality. Furthermore, the XGBoost classifier differentiates between depressed and non-depressed individuals. As a result, the proposed method uses the DAIC-WOZ dataset from USC for detecting depressions, achieving an accuracy of 97.02%, precision of 97.02%, recall of 97.02%, F1-score of 97.02%, RMSE of 2.00, and MAE of 0.9, making it a promising tool for autonomous depression detection. © 2024 St. Petersburg Federal Research Center of the Russian Academy of Sciences. All rights reserved. | E20: FALSE | J20: TRUE | L20: =IF(OR(Table1[[#This Row],[Does not regard DAIC-WOZ]]=TRUE,Table1[[#This Row],[Does not use MAE]]=TRUE,Table1[[#This Row],[Does not introduce new model]]=TRUE,Table1[[#This Row],[Not in English]]=TRUE,Table1[[#This Row],[Not retrieved]]=TRUE),TRUE,FALSE) -> TRUE | AF20: =IF(NOT(Table1[[#This Row],[Data modality]] = ""), NOT(OR(Table1[[#This Row],[Data preprocessing]] = "-", Table1[[#This Row],[Data partitioning]] = "-", Table1[[#This Row],[Partitions disjoint level]] = "-", Table1[[#This Row],[Model description]] ="-", Table1[[#This Row],[Training details]] = "-", Table1[[#This Row],[Final model selection]] = "-", Table1[[#This Row],[Discarded after full-text review]])),"")
A21: Gaze Behavior based Depression Severity Estimation | B21: https://doi.org/10.1109/PRML59573.2023.10348319 | C21: Scopus | D21: Depression is a severe mental illness that affects millions of people's lives Every year, more than 700,000 individuals choose to commit suicide due to depression. Early screening of patients with depression is challenging, making it critical to find methods that can aid doctors in quickly identifying potential patients. Currently, a significant number of depression severity estimation tasks focus on text, speech, and vision, but the exploration of the relationship between eye gaze behavior and depression is incomplete. This paper aims to explore the mapping relationship between eye gaze behavior and depression. We propose an integrated method to estimate depression severity using eye gaze behavior data. We formulate a more reasonable representation of gaze direction by expressing it as the angle of deflection. We employ a deep residual shrinkage network with channel-wise thresholds (DRSN-CW) to process the input gaze sequence and estimate the depression severity score. Moreover, we introduce label distribution learning to represent more fine-grained score information and alleviate the overfitting problem associated with small datasets, enhancing the reliability of depression severity estimation. We train and validate our model on the Distress Analysis Interview Corpus - Wizard of Oz (DAIC-WOZ) dataset, achieving an F1 score of 0.769, and reducing the mean absolute error (MAE) to 3.971 and root mean square error (RMSE) to 5.141. The results demonstrate significant improvement in the depression severity estimation task compared to previous tasks. © 2023 IEEE. | E21: FALSE | L21: =IF(OR(Table1[[#This Row],[Does not regard DAIC-WOZ]]=TRUE,Table1[[#This Row],[Does not use MAE]]=TRUE,Table1[[#This Row],[Does not introduce new model]]=TRUE,Table1[[#This Row],[Not in English]]=TRUE,Table1[[#This Row],[Not retrieved]]=TRUE),TRUE,FALSE) -> FALSE | M21: - | N21: 107 interviews for training and 35 for validation | O21: - | P21: - | Q21: - | R21: - | T21: V | U21: 3.971 | V21: 5.141 | W21: - | X21: - | Y21: - | Z21: - | AA21: No | AB21: No | AC21: No | AD21: No | AF21: =IF(NOT(Table1[[#This Row],[Data modality]] = ""), NOT(OR(Table1[[#This Row],[Data preprocessing]] = "-", Table1[[#This Row],[Data partitioning]] = "-", Table1[[#This Row],[Partitions disjoint level]] = "-", Table1[[#This Row],[Model description]] ="-", Table1[[#This Row],[Training details]] = "-", Table1[[#This Row],[Final model selection]] = "-", Table1[[#This Row],[Discarded after full-text review]])),"") -> FALSE | AG21: Lack of description of validation set preprocessing. Training partition was disjoint into 382 seconds fragments, however validation partition disjoint level is not disclosed. Model hyperparameters are not disclosed (number of layers, dimensionality of each layer, convolutional kernels etc.). Training details are not disclosed (optimizer, learning rate, number of epochs). Training details are not disclosed (optimizer, learning rate, number of epochs)
A22: Enhancing Depression Detection: Employing Autoencoders and Linguistic Feature Analysis with BERT and LSTM Model | B22: https://doi.org/10.1109/RusAutoCon58002.2023.10272795 | C22: Scopus | D22: Depression is an abstinent health ailment that affronts several people globally, affecting a consistent decline in mood resulting in a trivial impact on their emotions. The article centers around the utilization of BERT based features and Autoencoders to identify depression from textual input, while also exploring gender identity variations. The study emphasizes the importance of feature engineering for text data obtained from the DAIC_WOZ benchmark dataset. By employing BERT embeddings, which capture the semantic meaning of text, in combination with Autoencoders and additional quantitative characteristics such as PHQ-8 participant feedback, assessment of absolutist word usage, and gender details, the model's performance is significantly improved. We conduct trials with BERT embeddings that encode the textual meaning to extract text characteristics. These features are subsequently combined using Autoencoders. Our method surpasses the performance of the baseline models, achieving an accuracy of 95.5%. Additionally, the mean absolute error (MAE) is measured at 3.75 and the root mean squared error (RMSE) at 5.02, demonstrating the exceptional performance for binary depression classification. These discoveries reveal the capacity of machine learning in mental health investigation, especially when considering gender disparities. © 2023 IEEE. | E22: FALSE | L22: =IF(OR(Table1[[#This Row],[Does not regard DAIC-WOZ]]=TRUE,Table1[[#This Row],[Does not use MAE]]=TRUE,Table1[[#This Row],[Does not introduce new model]]=TRUE,Table1[[#This Row],[Not in English]]=TRUE,Table1[[#This Row],[Not retrieved]]=TRUE),TRUE,FALSE) -> FALSE | M22: - | N22: 148 interviews for training and 41 for testing | O22: - | P22: - | Q22: - | R22: - | T22: T | U22: 3.75 | V22: 5.02 | W22: 0.76 | X22: - | Y22: - | Z22: - | AA22: No | AB22: No | AC22: - | AD22: No | AF22: =IF(NOT(Table1[[#This Row],[Data modality]] = ""), NOT(OR(Table1[[#This Row],[Data preprocessing]] = "-", Table1[[#This Row],[Data partitioning]] = "-", Table1[[#This Row],[Partitions disjoint level]] = "-", Table1[[#This Row],[Model description]] ="-", Table1[[#This Row],[Training details]] = "-", Table1[[#This Row],[Final model selection]] = "-", Table1[[#This Row],[Discarded after full-text review]])),"") -> FALSE | AG22: Data preprocessing description is poor and chaotic: „To minimize noise in text data, commonly used words such as "and," "the," and "is" that lack significant meaning are usually eliminated”. For some reason correlation analysis is performed within AVEC 2019 dataset. Partitions disjoint level is not disclosed. Inconsistencies in model description. Autors state extraction of „767 embeddings”, supposedly meaning „767 dimensional embeddings”, hovewer BERT model produces 768-dimensional vectors. Number of LSTM layers is not disclosed. Autoencoder dimensionality is not disclosed. Training description lacks details (optimizer, early stopping setting).
A23: A textual-based featuring approach for depression detection using machine learning classifiers and social media texts | B23: https://doi.org/10.1016/j.compbiomed.2021.104499 | C23: ScienceDirect | D23: Depression is one of the leading causes of suicide worldwide. However, a large percentage of cases of depression go undiagnosed and, thus, untreated. Previous studies have found that messages posted by individuals with major depressive disorder on social media platforms can be analysed to predict if they are suffering, or likely to suffer, from depression. This study aims to determine whether machine learning could be effectively used to detect signs of depression in social media users by analysing their social media posts—especially when those messages do not explicitly contain specific keywords such as ‘depression’ or ‘diagnosis’. To this end, we investigate several text preprocessing and textual-based featuring methods along with machine learning classifiers, including single and ensemble models, to propose a generalised approach for depression detection using social media texts. We first use two public, labelled Twitter datasets to train and test the machine learning models, and then another three non-Twitter depression-class-only datasets (sourced from Facebook, Reddit, and an electronic diary) to test the performance of our trained models against other social media sources. Experimental results indicate that the proposed approach is able to effectively detect depression via social media texts even when the training datasets do not contain specific keywords (such as ‘depression’ and ‘diagnose’), as well as when unrelated datasets are used for testing. | E23: TRUE | L23: =IF(OR(Table1[[#This Row],[Does not regard DAIC-WOZ]]=TRUE,Table1[[#This Row],[Does not use MAE]]=TRUE,Table1[[#This Row],[Does not introduce new model]]=TRUE,Table1[[#This Row],[Not in English]]=TRUE,Table1[[#This Row],[Not retrieved]]=TRUE),TRUE,FALSE) -> FALSE | AF23: =IF(NOT(Table1[[#This Row],[Data modality]] = ""), NOT(OR(Table1[[#This Row],[Data preprocessing]] = "-", Table1[[#This Row],[Data partitioning]] = "-", Table1[[#This Row],[Partitions disjoint level]] = "-", Table1[[#This Row],[Model description]] ="-", Table1[[#This Row],[Training details]] = "-", Table1[[#This Row],[Final model selection]] = "-", Table1[[#This Row],[Discarded after full-text review]])),"")
A24: A Multimodal Approach for Detection and Assessment of Depression Using Text, Audio and Video | B24: https://doi.org/10.1007/s43657-023-00152-8 | C24: Scopus | D24: Depression is one of the most common mental disorders, and rates of depression in individuals increase each year. Traditional diagnostic methods are primarily based on professional judgment, which is prone to individual bias. Therefore, it is crucial to design an effective and robust diagnostic method for automated depression detection. Current artificial intelligence approaches are limited in their abilities to extract features from long sentences. In addition, current models are not as robust with large input dimensions. To solve these concerns, a multimodal fusion model comprised of text, audio, and video for both depression detection and assessment tasks was developed. In the text modality, pre-trained sentence embedding was utilized to extract semantic representation along with Bidirectional long short-term memory (BiLSTM) to predict depression. This study also used Principal component analysis (PCA) to reduce the dimensionality of the input feature space and Support vector machine (SVM) to predict depression based on audio modality. In the video modality, Extreme gradient boosting (XGBoost) was employed to conduct both feature selection and depression detection. The final predictions were given by outputs of the different modalities with an ensemble voting algorithm. Experiments on the Distress analysis interview corpus wizard-of-Oz (DAIC-WOZ) dataset showed a great improvement of performance, with a weighted F1 score of 0.85, a Root mean square error (RMSE) of 5.57, and a Mean absolute error (MAE) of 4.48. Our proposed model outperforms the baseline in both depression detection and assessment tasks, and was shown to perform better than other existing state-of-the-art depression detection methods. © International Human Phenome Institutes (Shanghai) 2024. | E24: FALSE | L24: =IF(OR(Table1[[#This Row],[Does not regard DAIC-WOZ]]=TRUE,Table1[[#This Row],[Does not use MAE]]=TRUE,Table1[[#This Row],[Does not introduce new model]]=TRUE,Table1[[#This Row],[Not in English]]=TRUE,Table1[[#This Row],[Not retrieved]]=TRUE),TRUE,FALSE) -> FALSE | M24: Removal of interviewer turns, COVAREP, MFCCs, PCA dimensionality reduction, OpenFACE | N24: Default | O24: Interview | P24: BERT-BiLSTM, SVM, XGBoost | Q24: - | R24: - | T24: V-A-T | U24: 4.48 | V24: 5.57 | W24: - | X24: - | Y24: - | Z24: - | AA24: No | AB24: Yes | AC24: No | AD24: No | AF24: =IF(NOT(Table1[[#This Row],[Data modality]] = ""), NOT(OR(Table1[[#This Row],[Data preprocessing]] = "-", Table1[[#This Row],[Data partitioning]] = "-", Table1[[#This Row],[Partitions disjoint level]] = "-", Table1[[#This Row],[Model description]] ="-", Table1[[#This Row],[Training details]] = "-", Table1[[#This Row],[Final model selection]] = "-", Table1[[#This Row],[Discarded after full-text review]])),"") -> FALSE | AG24: Training details are not disclosed. Convergence criteria for text modality are not disclosed.
